Workbook

Sheet 00_README
A1: OBI BATCH RECORD WORKBOOK
A4: Batch ID | B4: OB-FER-26-003 (legacy ID: OBI-26-FER-003)
A5: OB-EXP Ref | B5: FER-003
A6: Transcribed By | B6: LC / 28-05-2026
A7: Verified By | B7: MS / 28-05-2026
A9: CELL CONVENTIONS
A10: Plain bordered cells | B10: Enter data here.
A11: Grey italic cells | B11: Calculated. Do not type in these - typing destroys the formula.
A12: Blue cells | B12: Field names. Do not edit.
A14: TERMINOLOGY
A15: Seed | B15: The propagation culture grown up from a cryovial or a previous seed stage. Seed media, seed flask, seed growth.
A16: Batch | B16: The production flask containing the grain substrate. Batch media, batch inoculation, batch growth.
A17: Transfer | B17: Moving seed into the next seed stage or into the batch flask.
A19: ORDER OF WORK
A20: Why this order | B20: Seed is prepared and set to incubate first, because the batch cannot be inoculated without it. Batch media prep and sterilisation happen during the seed incubation wait, so tabs 04 and 05 sit between seed inoculation and seed growth.
A21: Seed stages | B21: Seed tabs carry a Seed Stage column. One stage is usual, two occasionally, three rarely - add a row per stage rather than copying tabs.
A23: ANALYSIS TAB
A24: How it works | B24: ANALYSIS is calculated, not typed. It pulls pH and OD from 09_BATCH GROWTH LOG and absorbance and titre from 11_ASSAY RESULTS, matching on Flask ID and Log hr, and derives concentrations and percent lactic acid. Enter data on the numbered tabs only.
A25: Matching key | B25: Flask ID and Log hr must be identical across tabs for the match to work. Flask ID is a dropdown sourced from the flask index on 01_BATCH INFO - always pick, never type.
A27: ASSUMPTIONS
A28: Standard curve | B28: One anthrone and one DNS curve per workbook, held on 10_STANDARD CURVES. If a second curve is run for this batch, use a second workbook or the derived concentrations will be wrong.
A29: Concordant titre | B29: The concordant mean averages Titre 2 and Titre 3, treating Titre 1 as the rough trial. If a different pair was concordant, overwrite the mean and note it in Remarks.
A30: Lactic acid | B30: % lactic acid (w/v) = titre (ml) x normality x 0.09008 / sample volume (ml) x 100.
A31: Total output | B31: Supernatant volume added to dried pellet weight on a 1 g per ml basis.
A32: Source of truth | B32: Where this workbook and the signed paper form disagree, the paper form governs. OxyOS remains the system of record.

Sheet 01 BATCH INFO
A1: 01 BATCH INFO
A4: Batch ID (OxyOS) | B4: OB-FER-26-003 | C4: OB-EXP Ref | D4: FER-003
A5: Trial Title / Objective | B5: Fermentation batch | C5: Date Started | D5: 26-05-2026
A6: Analyst | B6: SK | C6: No. of Flasks in this Batch | D6: 2
A8: FLASK INDEX
A10: S.No | B10: Flask ID | C10: Treatment / Arm | D10: Notes
A11: 1 | B11: F1 | C11: SKU-1 | D11: Duplicate
A12: 2 | B12: F2 | C12: SKU-1 | D12: Duplicate
A14: OxyOS Batch Record ID | B14: OBI-26-FER-003 | C14: Transcribed By / Date | D14: LC / 28-05-2026
A15: Verified By (2nd person) / Date | B15: MS / 28-05-2026 | C15: Discrepancy Noted (Y/N) | D15: N

Sheet 02 SEED MEDIA PREP
A1: 02 SEED MEDIA PREP
A3: S.No | B3: Seed Stage | C3: Media Type / Name | D3: Media Composition / SOP Ref | E3: Volume Prepared (ml) | F3: pH Before Steril. | G3: pH After Steril. | H3: Autoclave Log Ref | I3: Cycle ID | J3: Sterility Ref (pre-inoc) | K3: Prepared By
A4: 1 | B4: N/A | C4: N/A - no propagation stage; inoculum added direct | D4: OB-LP-001 Protocol 1 | E4: N/A | F4: N/A | G4: N/A | H4: N/A | I4: N/A | J4: N/A | K4: N/A
A6: TRANSCRIPTION TO OxyOS
A7: OxyOS Seed Record ID | B7: N/A | C7: Transcribed By / Date | D7: LC / 28-05-2026
A8: Verified By (2nd person) / Date | B8: MS / 28-05-2026 | C8: Discrepancy Noted (Y/N) | D8: N

Sheet 03_SEED INOCULATION
A1: 03 SEED INOCULATION
A3: S.No | B3: Seed Stage | C3: Source | D3: Cryovial ID / Prev Stage Ref | E3: Thaw Method | F3: Thaw Duration | G3: Post-thaw Visual Check | H3: Contam. Signs | I3: Inoculation Vol / Loop | J3: Seed Vessel / Flask ID | K3: Inoculation Date-Time | L3: Incubator Log Ref | M3: Incubator Type | N3: Temp Set (C) / RPM or CO2 | O3: Performed By
A4: 1 | B4: N/A - direct | C4: Cryovial (direct, no propagation) | D4: RCB-001 | E4: Vial ID not recorded in the legacy sheet | F4: N/A - no thaw step recorded | G4: Not recorded | H4: N | I4: 5 ml thawed vial dispensed across F1 and F2 - per-flask % conflicts, see 20_DEVIATIONS | J4: F1, F2 | K4: 26-05-2026 08:55 | L4: ACE-BT/CO2INC/001 | M4: CO2 | N4: 37 C / 5% CO2 | O4: MS
A6: TRANSCRIPTION TO OxyOS
A7: OxyOS Seed Record ID | B7: N/A | C7: Transcribed By / Date | D7: LC / 28-05-2026
A8: Verified By (2nd person) / Date | B8: MS / 28-05-2026 | C8: Discrepancy Noted (Y/N) | D8: N

Sheet 04_BATCH MEDIA PREP
A1: 04 BATCH MEDIA PREP
A3: SUBSTRATES
A4: Substrate | B4: Target Qty (g) | C4: Actual Qty (g) | D4: Deviation (g)
A5: Sprouted Ragi | B5: 10 | C5: 10 | D5: =IFERROR(IF(OR(B5="",C5=""),"",C5-B5),"") -> 0
A6: Karuppu Kavuni (KK) Black Rice | B6: 4 | C6: 4 | D6: =IFERROR(IF(OR(B6="",C6=""),"",C6-B6),"") -> 0
A7: Urad Dal | B7: 6 | C7: 6 | D7: =IFERROR(IF(OR(B7="",C7=""),"",C7-B7),"") -> 0
D8: =IFERROR(IF(OR(B8="",C8=""),"",C8-B8),"")
A10: PREPARATION
A11: Water / Liquid Vol. Added (ml) | B11: 400 | C11: pH Before Adj. | D11: NA
A12: pH After Adj. | B12: NA | C12: Adjustment Agent (if any) | D12: NA
A13: Hot-stir Step Completed (Y/N) | B13: NA | C13: Time Completed | D13: NA
A15: STERILISATION
A16: Autoclave - Equipment Log Ref | B16: N/A - media not autoclaved for this batch | C16: Sterilisation Cycle ID | D16: NA
A17: Media Sterility Check (Y/N) | B17: Y | C17: Sterility Ref (15_PLATING / 17_MICROSCOPY) | D17: PL-01 (see 15_PLATING)
A18: Prepared By / Date-Time | B18: SK / 26-05-2026 | C18: Deviation Noted (Y/N + note) | D18: 400 ml prepared for 2 flasks = 200 ml per flask
A20: TRANSCRIPTION TO OxyOS
A21: OxyOS Batch Record ID | B21: OBI-26-FER-003 | C21: Transcribed By / Date | D21: LC / 28-05-2026
A22: Verified By (2nd person) / Date | B22: MS / 28-05-2026 | C22: Discrepancy Noted (Y/N) | D22: N

Sheet 05_INCUBATION SETUP
A1: 05 INCUBATION SETUP
A3: Incubator - Equipment Log Ref | B3: ACE-BT/CO2INC/001 | C3: Incubator Type | D3: CO2
A4: Temp Set (deg C) | B4: 37 | C4: RPM (if shaker) / CO2 % (if CO2) | D4: 0.05
A5: Set By / Date-Time | B5: MS / 26-05-2026 08:55 | D5: N
A7: TRANSCRIPTION TO OxyOS
A8: OxyOS Batch Record ID | B8: OBI-26-FER-003 | C8: Transcribed By / Date | D8: LC / 28-05-2026
A9: Verified By (2nd person) / Date | B9: MS / 28-05-2026 | C9: Discrepancy Noted (Y/N) | D9: N

Sheet 06_SEED GROWTH LOG
A1: 06 SEED GROWTH LOG
A4: S.No | B4: Seed Stage | C4: Time | D4: Elapsed (hr) | E4: pH | F4: OD | G4: Sample Vol Taken (ml) | H4: Remarks | I4: Recorded By
A5: 1 | B5: N/A | C5: N/A | D5: N/A | E5: N/A | F5: N/A - OD not valid in curd matrix | G5: N/A | H5: No propagation stage - inoculum added directly to the batch flasks. CFU not enumerated. Reference range for fresh same-day curd 1.4x10^7 to 2.5x10^8 CFU/ml (literature, not measured). | I5: N/A
A9: TRANSCRIPTION TO OxyOS
A10: OxyOS Seed Record ID | B10: N/A | C10: Transcribed By / Date | D10: LC / 28-05-2026
A11: Verified By (2nd person) / Date | B11: MS / 28-05-2026 | C11: Discrepancy Noted (Y/N) | D11: N

Sheet 07_TRANSFER DECISION
A1: 07 TRANSFER DECISION
A2: Target versus actual at transfer, and where the seed went. One row per seed stage.
A4: S.No | B4: Seed Stage | C4: Target OD | D4: Target pH | E4: Actual OD | F4: Actual pH | G4: Criteria Met | H4: If Not Met - justification | I4: Vol Out (ml) | J4: Transfer Date-Time | K4: Transferred To | L4: Next Stage Ref / Flask ID | M4: Sterility Ref (final) | N4: Generated By | O4: Verified By
A5: 1 | B5: N/A - direct | C5: N/A - OD not a transfer criterion | D5: N/A | E5: N/A - OD not valid in curd matrix | F5: Not recorded | G5: Yes | H5: Direct inoculation - no transfer criteria applied | I5: 5 ml thawed vial dispensed across F1 and F2 - per-flask % conflicts, see 20_DEVIATIONS | J5: 26-05-2026 08:55 | K5: Batch flask | L5: F1, F2 | M5: N/A | N5: MS | O5: LC
A6: 2
A7: 3
A8: 4
A9: 5
A10: 6
A13: TRANSCRIPTION TO OxyOS
A14: OxyOS Seed Record ID | B14: N/A | C14: Transcribed By / Date | D14: LC / 28-05-2026
A15: Verified By (2nd person) / Date | B15: MS / 28-05-2026 | C15: Discrepancy Noted (Y/N) | D15: N

Sheet 08_BATCH INOCULATION
A1: 08 BATCH INOCULATION
A4: S.No | B4: Flask ID | C4: Treatment / Arm | D4: Seed Stage Used | E4: Seed Vol / % Added | F4: Inoculation Date-Time | G4: Flask Vol (ml) | H4: Initial pH | I4: Initial Temp (C) | J4: Sterility Chk - Media | K4: Sterility Chk - Seed | L4: Inoculated By
A5: 1 | B5: F1 | C5: SKU-1 | D5: N/A - direct | E5: 5 ml thawed vial dispensed across F1 and F2 - per-flask % conflicts, see 20_DEVIATIONS | F5: 26-05-2026 08:55 | G5: 201 | H5: 5.83 | I5: 37 | J5: Y | K5: Y | L5: MS
A6: 2 | B6: F2 | C6: SKU-1 | D6: N/A - direct | E6: 5 ml thawed vial dispensed across F1 and F2 - per-flask % conflicts, see 20_DEVIATIONS | F6: 26-05-2026 08:55 | G6: 201 | H6: 5.7 | I6: 37 | J6: Y | K6: Y | L6: MS
A8: OxyOS Batch Record ID | B8: OBI-26-FER-003 | C8: Transcribed By / Date | D8: LC / 28-05-2026
A9: Verified By (2nd person) / Date | B9: MS / 28-05-2026 | C9: Discrepancy Noted (Y/N) | D9: N

Sheet 09_BATCH GROWTH LOG
A1: 09 BATCH GROWTH LOG
A4: S.No | B4: Flask ID | C4: Log hr | D4: Date | E4: Time | F4: pH | G4: OD | H4: Sterility chk | I4: Sample Pulled (Y/N) | J4: Remarks | K4: Recorded By
A5: 1 | B5: F1 | C5: 0 | D5: 26-05-2026 | E5: 09:00 | F5: 5.83 | G5: NA | H5: Clear | I5: Y | J5: NA | K5: SK
A6: 2 | B6: F1 | C6: 6 | D6: 26-05-2026 | E6: 15:00 | F6: 5.55 | G6: NA | H6: Clear | I6: Y | J6: pH Reconstructed retrospectively - not contemporaneous | K6: SK
A7: 3 | B7: F1 | C7: 12 | D7: 26-05-2026 | E7: 21:00 | F7: 5.35 | G7: NA | H7: Clear | I7: Y | J7: pH Reconstructed retrospectively - not contemporaneous | K7: LC
A8: 4 | B8: F1 | C8: 24 | D8: 27-05-2026 | E8: 09:00 | F8: 5.17 | G8: NA | H8: Clear | I8: Y | J8: NA | K8: SK
A9: 5 | B9: F1 | C9: 30 | D9: 27-05-2026 | E9: 15:00 | F9: 5.13 | G9: NA | H9: Clear | I9: Y | J9: pH Reconstructed retrospectively - not contemporaneous | K9: SK
A10: 6 | B10: F1 | C10: 36 | D10: 27-05-2026 | E10: 21:00 | F10: 5.11 | G10: NA | H10: Clear | I10: Y | J10: pH Reconstructed retrospectively - not contemporaneous | K10: LC
A11: 7 | B11: F1 | C11: 48 | D11: 28-05-2026 | E11: 09:00 | F11: 5.09 | G11: NA | H11: Clear | I11: Y | J11: NA | K11: SK
A12: 8 | B12: F2 | C12: 0 | D12: 26-05-2026 | E12: 09:00 | F12: 5.7 | G12: NA | H12: Clear | I12: Y | J12: NA | K12: SK
A13: 9 | B13: F2 | C13: 6 | D13: 26-05-2026 | E13: 15:00 | F13: 5.58 | G13: NA | H13: Clear | I13: Y | J13: pH Reconstructed retrospectively - not contemporaneous | K13: SK
A14: 10 | B14: F2 | C14: 12 | D14: 26-05-2026 | E14: 21:00 | F14: 5.48 | G14: NA | H14: Clear | I14: Y | J14: pH Reconstructed retrospectively - not contemporaneous | K14: LC
A15: 11 | B15: F2 | C15: 24 | D15: 27-05-2026 | E15: 09:00 | F15: 5.4 | G15: NA | H15: Clear | I15: Y | J15: NA | K15: SK
A16: 12 | B16: F2 | C16: 30 | D16: 27-05-2026 | E16: 15:00 | F16: 5.3 | G16: NA | H16: Clear | I16: Y | J16: pH Reconstructed retrospectively - not contemporaneous | K16: SK
... A18: 14 | B18: F2 | C18: 48 | D18: 28-05-2026 | E18: 09:00 | F18: 5.12 | G18: NA | H18: Clear | I18: Y | J18: NA | K18: SK

Sheet 10_STANDARD CURVES
A1: 10 STANDARD CURVES
A2: Slope, intercept and R squared feed the derived concentrations on ANALYSIS. Check R squared before trusting any result.
A4: ANTHRONE (625 nm) | E4: DNS (540 nm)
A5: Std No. | B5: Conc (ug/ml) | C5: Absorbance | E5: Std No. | F5: Conc (ug/ml) | G5: Absorbance
A6: Blank | E6: Blank | F6: NA | G6: NA
A7: 1 | E7: 1 | F7: NA | G7: NA
A8: 2 | E8: 2 | F8: NA | G8: NA
A9: 3 | E9: 3 | F9: NA | G9: NA
A10: 4 | E10: 4 | F10: NA | G10: NA
A11: 5 | E11: 5 | F11: NA | G11: NA
A12: 6 | E12: 6 | F12: NA | G12: NA
A13: 7 | E13: 7 | F13: NA | G13: NA
A15: Slope | B15: =IFERROR(SLOPE(C6:C13,B6:B13),"") | E15: Slope | F15: NA
A16: Intercept | B16: =IFERROR(INTERCEPT(C6:C13,B6:B13),"") | E16: Intercept | F16: NA
A17: R squared | B17: =IFERROR(RSQ(C6:C13,B6:B13),"") | E17: R squared | F17: NA
A19: Run Date | B19: NA | E19: Run Date | F19: NA
A20: Analyst | B20: NA | E20: Analyst | F20: NA
A21: Spectrophotometer Log Ref | B21: NA | E21: Spectrophotometer Log Ref | F21: NA
A23: Range 0-60 ug/ml. Dilute before the reaction, never after colour development. | E23: Reducing sugars.

Sheet 11_ASSAY RESULTS
A1: 11 ASSAY RESULTS
A4: S.No | B4: Flask ID | C4: Log hr | D4: Date | E4: Anthrone Abs | F4: Anthrone Dil Fac | G4: DNS Abs | H4: DNS Dil Fac | I4: Sample Vol Titrated (ml) | J4: NaOH Normality | K4: Titre 1 (ml) | L4: Titre 2 (ml) | M4: Titre 3 (ml) | N4: Remarks | O4: Recorded By | P4: KEY (auto)
P5: =IF(B5="","",B5&"|"&C5)
P6: =IF(B6="","",B6&"|"&C6)
P7: =IF(B7="","",B7&"|"&C7)
P8: =IF(B8="","",B8&"|"&C8)
P9: =IF(B9="","",B9&"|"&C9)
P10: =IF(B10="","",B10&"|"&C10)
P11: =IF(B11="","",B11&"|"&C11)
P12: =IF(B12="","",B12&"|"&C12)
P13: =IF(B13="","",B13&"|"&C13)
P14: =IF(B14="","",B14&"|"&C14)
P15: =IF(B15="","",B15&"|"&C15)
P16: =IF(B16="","",B16&"|"&C16)
... P44: =IF(B44="","",B44&"|"&C44)

Sheet 12_HARVEST
A1: 12 HARVEST
A2: One row per flask at harvest.
A4: S.No | B4: Flask ID | C4: Harvest Log hr | D4: Harvest Date-Time | E4: Final pH | F4: Final OD | G4: Broth Weight (g) | H4: Broth Volume (ml) | I4: Sterility Chk Done | J4: Harvested By | K4: Disposition | L4: Storage Location / Temp | M4: Storage Start Date-Time
A5: 1 | B5: F1 | C5: 48 | D5: 28-05-2026 09:00 | E5: 5.12 | F5: NA | G5: NA | H5: 185 | I5: Y | J5: SK | K5: Stored | L5: ACE-BT/REF/001 Refrigerator / 4 C | M5: 30-05-2026
A6: 2 | B6: F2 | C6: 48 | D6: 28-05-2026 09:00 | E6: 5.11 | F6: NA | G6: NA | H6: 185 | I6: Y | J6: SK | K6: Stored | L6: ACE-BT/REF/001 Refrigerator / 4 C | M6: 30-05-2026

Sheet 13_DOWNSTREAM
A1: 13 DOWNSTREAM
A2: One row per flask per step. Seq numbers the steps in the order performed for that flask; Stream says which material the step acted on. Equipment cycle detail stays in the equipment log book - enter only its reference.
A4: S.No | B4: Flask ID | C4: Seq | D4: Step | E4: Stream Acted On | F4: Equipment Log Ref | G4: Wt/Vol In | H4: Wt/Vol Out | I4: Start Time | J4: End Time | K4: Performed By | L4: Remarks
A5: 1 | B5: F1 | C5: 1 | D5: Centrifuging | E5: Whole broth | F5: ACE-BT/CENT/001 | G5: 185 | H5: 110 | I5: 13:00 | J5: 17:00 | K5: SK | L5: Supernatant drawn off, pellet retained
A6: 2 | B6: F1 | C6: 2 | D6: Drying | E6: Pellet | F6: ACE-BT/HAO/001 | G6: NA | H6: 4 | I6: 17:00 | J6: 09:00 | K6: SK | L6: 29-05-2026; overnight dry
A7: 3 | B7: F2 | C7: 1 | D7: Centrifuging | E7: Whole broth | F7: ACE-BT/CENT/001 | G7: 185 | H7: 110 | I7: 13:00 | J7: 17:00 | K7: SK | L7: Supernatant drawn off, pellet retained
A8: 4 | B8: F2 | C8: 2 | D8: Drying | E8: Pellet | F8: ACE-BT/HAO/001 | G8: NA | H8: 4 | I8: 17:00 | J8: 09:00 | K8: SK | L8: 29-05-2026; overnight dry
A38: S.No | B38: Flask ID | C38: Supernatant (ml) | D38: Pellet Wet (g) | E38: Pellet Dried (g) | F38: Total Output (g) | G38: Output Stored At | H38: Container / Label Ref | I38: Completed By
A39: 1 | B39: F1 | C39: 110 | D39: 75 | E39: 4 | F39: =IFERROR(IF(AND(C39="",E39=""),"",N(C39)+N(E39)),"") -> 114 | G39: ACE-BT/REF/001 Refrigerator | H39: NA | I39: SK
A40: 2 | B40: F2 | C40: 110 | D40: 75 | E40: 4 | F40: =IFERROR(IF(AND(C40="",E40=""),"",N(C40)+N(E40)),"") -> 114 | G40: ACE-BT/REF/001 Refrigerator | H40: NA | I40: SK
F41: =IFERROR(IF(AND(C41="",E41=""),"",N(C41)+N(E41)),"")
F42: =IFERROR(IF(AND(C42="",E42=""),"",N(C42)+N(E42)),"")
F43: =IFERROR(IF(AND(C43="",E43=""),"",N(C43)+N(E43)),"")
F44: =IFERROR(IF(AND(C44="",E44=""),"",N(C44)+N(E44)),"")
F45: =IFERROR(IF(AND(C45="",E45=""),"",N(C45)+N(E45)),"")
F46: =IFERROR(IF(AND(C46="",E46=""),"",N(C46)+N(E46)),"")
F47: =IFERROR(IF(AND(C47="",E47=""),"",N(C47)+N(E47)),"")
F48: =IFERROR(IF(AND(C48="",E48=""),"",N(C48)+N(E48)),"")

Sheet 14_PRODUCT PREP
A1: 14 PRODUCT PREP & ANALYSIS
A3: Batch ID / OB-EXP Ref | B3: OB-FER-26-003 / FER-003 | C3: Date | D3: 28-05-2026
A4: Source Stream | B4: Both | C4: Source Flask ID(s) | D4: F1, F2
A5: Analyst | B5: SK
A7: Component / Parameter | B7: F1 | C7: F2 | D7: F3 | E7: F4
A8: A. FORMULATION - quantities per variant
A9: Pellet (g) | B9: 4 | C9: 4 | D9: NA | E9: NA
A10: Supernatant (ml) | B10: 110 | C10: 110 | D10: NA | E10: NA
A11: Milk (ml) | B11: NA | C11: NA | D11: NA | E11: NA
A12: Sugar (g) | B12: NA | C12: NA | D12: NA | E12: NA
A13: Total volume / weight | B13: 114 | C13: 114 | D13: NA | E13: NA
A14: B. pH
A15: pH before addition | B15: 5.11 | C15: 5.12 | D15: NA | E15: NA
A16: pH after addition | B16: 5.08 | C16: 5.12 | D16: NA | E16: NA
A17: C. SAMPLES PULLED (Y/N - results on the referenced tab)
A18: Anthrone before (11_ASSAY RESULTS) | B18: NA | C18: NA | D18: NA | E18: NA
A19: Anthrone after (11_ASSAY RESULTS) | B19: NA | C19: NA | D19: NA | E19: NA
A20: Plating (15_PLATING) | B20: NA | C20: NA | D20: NA | E20: NA
A21: D. SENSORY ANALYSIS
A22: Colour | B22: Golden Brown | C22: Golden Brown | D22: NA | E22: NA
A23: Appearance | B23: Clean and transparent | C23: Clean and transparent | D23: NA | E23: NA
A24: Odour | B24: Tangy and clean | C24: Tangy and clean | D24: NA | E24: NA
A25: Taste | B25: Tangy with a sour aftertaste | C25: Tangy with a sour aftertaste | D25: NA | E25: NA
A26: Texture | B26: Clear liquid | C26: Clear liquid | D26: NA | E26: NA
A27: Mouthfeel | B27: Good | C27: Good | D27: NA | E27: NA
A28: Overall acceptability | B28: Good | C28: Good | D28: NA | E28: NA
A29: E. SIGN-OFF
A30: Prepared by / time | B30: SK / 28-05-2026 | C30: SK / 28-05-2026 | D30: NA | E30: NA
A31: Analysed by / time | B31: SK / 28-05-2026 | C31: SK / 28-05-2026 | D31: NA | E31: NA
A33: TRANSCRIPTION TO OxyOS
A34: OxyOS Product Record ID | B34: OBI-26-FER-003 | C34: Transcribed By / Date | D34: LC / 28-05-2026
A35: Verified By (2nd person) / Date | B35: MS / 28-05-2026 | C35: Discrepancy Noted (Y/N) | D35: N

Sheet 15_PLATING
A1: 15 PLATING
A2: One row per READ. A plate read more than once takes one row per read - never overwrite a previous read.
A4: S.No | B4: Plate ID (Batch/Exp + log hr) | C4: Medium | D4: Inc. Temp (C) | E4: Plated Date-Time | F4: Expected Colony Description | G4: Read Date-Time | H4: Inc. Elapsed | I4: Colonies Observed (morphology) | J4: Matches Exp. | K4: Unexpected Growth - describe | L4: Result | M4: Disposal Date | N4: Disposed By | O4: Recorded By
A5: 1 | B5: PL-01 | C5: MRS | D5: 37 | E5: 26-05-2026 08:55 | F5: No growth expected (batch media sterility) | G5: 26-05-2026 08:55 | H5: Before inoculation | I5: No growth | J5: Y | K5: None | L5: Pass | M5: 28-05-2026 09:00 | N5: SK | O5: SK

Sheet 16_CFU
A1: 16 CFU ENUMERATION
A2: One row per sample per dilution. Record every replicate as read, including zero. For too-numerous-to-count, leave counts blank and write TNTC in Remarks.
A4: S.No | B4: Sample ID (Batch/Exp + log hr) | C4: Method | D4: Diluent | E4: Medium | F4: Inc. Temp / Duration | G4: Dilution (10^-n) | H4: Vol Plated (ml) | I4: Count R1 | J4: Count R2 | K4: Count R3 | L4: Mean Count | M4: CFU per ml | N4: Log10 CFU/ml | O4: Read Date-Time | P4: Remarks | Q4: Recorded By
A5: 1 | L5: =IFERROR(IF(COUNT(I5:K5)=0,"",AVERAGE(I5:K5)),"") | M5: =IFERROR(IF(OR(L5="",G5="",H5=""),"",L5/H5*POWER(10,G5)),"") | N5: =IFERROR(IF(M5="","",LOG10(M5)),"")
A6: 2 | L6: =IFERROR(IF(COUNT(I6:K6)=0,"",AVERAGE(I6:K6)),"") | M6: =IFERROR(IF(OR(L6="",G6="",H6=""),"",L6/H6*POWER(10,G6)),"") | N6: =IFERROR(IF(M6="","",LOG10(M6)),"")
A7: 3 | L7: =IFERROR(IF(COUNT(I7:K7)=0,"",AVERAGE(I7:K7)),"") | M7: =IFERROR(IF(OR(L7="",G7="",H7=""),"",L7/H7*POWER(10,G7)),"") | N7: =IFERROR(IF(M7="","",LOG10(M7)),"")
A8: 4 | L8: =IFERROR(IF(COUNT(I8:K8)=0,"",AVERAGE(I8:K8)),"") | M8: =IFERROR(IF(OR(L8="",G8="",H8=""),"",L8/H8*POWER(10,G8)),"") | N8: =IFERROR(IF(M8="","",LOG10(M8)),"")
A9: 5 | L9: =IFERROR(IF(COUNT(I9:K9)=0,"",AVERAGE(I9:K9)),"") | M9: =IFERROR(IF(OR(L9="",G9="",H9=""),"",L9/H9*POWER(10,G9)),"") | N9: =IFERROR(IF(M9="","",LOG10(M9)),"")
A10: 6 | L10: =IFERROR(IF(COUNT(I10:K10)=0,"",AVERAGE(I10:K10)),"") | M10: =IFERROR(IF(OR(L10="",G10="",H10=""),"",L10/H10*POWER(10,G10)),"") | N10: =IFERROR(IF(M10="","",LOG10(M10)),"")
A11: 7 | L11: =IFERROR(IF(COUNT(I11:K11)=0,"",AVERAGE(I11:K11)),"") | M11: =IFERROR(IF(OR(L11="",G11="",H11=""),"",L11/H11*POWER(10,G11)),"") | N11: =IFERROR(IF(M11="","",LOG10(M11)),"")
A12: 8 | L12: =IFERROR(IF(COUNT(I12:K12)=0,"",AVERAGE(I12:K12)),"") | M12: =IFERROR(IF(OR(L12="",G12="",H12=""),"",L12/H12*POWER(10,G12)),"") | N12: =IFERROR(IF(M12="","",LOG10(M12)),"")
A13: 9 | L13: =IFERROR(IF(COUNT(I13:K13)=0,"",AVERAGE(I13:K13)),"") | M13: =IFERROR(IF(OR(L13="",G13="",H13=""),"",L13/H13*POWER(10,G13)),"") | N13: =IFERROR(IF(M13="","",LOG10(M13)),"")
A14: 10 | L14: =IFERROR(IF(COUNT(I14:K14)=0,"",AVERAGE(I14:K14)),"") | M14: =IFERROR(IF(OR(L14="",G14="",H14=""),"",L14/H14*POWER(10,G14)),"") | N14: =IFERROR(IF(M14="","",LOG10(M14)),"")
A15: 11 | L15: =IFERROR(IF(COUNT(I15:K15)=0,"",AVERAGE(I15:K15)),"") | M15: =IFERROR(IF(OR(L15="",G15="",H15=""),"",L15/H15*POWER(10,G15)),"") | N15: =IFERROR(IF(M15="","",LOG10(M15)),"")
A16: 12 | L16: =IFERROR(IF(COUNT(I16:K16)=0,"",AVERAGE(I16:K16)),"") | M16: =IFERROR(IF(OR(L16="",G16="",H16=""),"",L16/H16*POWER(10,G16)),"") | N16: =IFERROR(IF(M16="","",LOG10(M16)),"")
... A28: 24 | L28: =IFERROR(IF(COUNT(I28:K28)=0,"",AVERAGE(I28:K28)),"") | M28: =IFERROR(IF(OR(L28="",G28="",H28=""),"",L28/H28*POWER(10,G28)),"") | N28: =IFERROR(IF(M28="","",LOG10(M28)),"")

Sheet 17_MICROSCOPY
A1: 17 MICROSCOPY
A2: One row per slide.
A4: S.No | B4: Slide ID (Batch/Exp + log hr, or Isolate ID) | C4: Date | D4: Time | E4: Stain | F4: Magnification | G4: Observation | H4: Microscope Log Ref | I4: Observed By
A5: 1 | B5: SL-01 | C5: 21-07-2026 | D5: 0.375 | E5: Gram | F5: 100 X | G5: No bacterial cells observed | I5: MS
A6: 2 | B6: SL-02 | C6: 22-07-2026 | D6: 0.375 | E6: Gram | F6: 100 X | G6: No bacterial cells observed | I6: MS
A7: 3 | B7: SL-03 | C7: 22-07-2026 | D7: 0.46875 | E7: Gram | F7: 100 X | G7: Gram-positive rods, small-sized, singly arranged | I7: MS
A8: 4 | B8: SL-04 | C8: 23-07-2026 | D8: 0.42708333 | E8: Gram | F8: 100 X | G8: Gram-positive rods, medium-sized, singly arranged | I8: MS
A9: 5 | B9: SL-05 | C9: 23-07-2026 | D9: 0.67708333 | E9: Gram | F9: 100 X | G9: Gram-positive rods, medium-sized, singly arranged | I9: MS
A10: 6 | B10: SL-06 | C10: 24-07-2026 | D10: 0.38541667 | E10: Gram | F10: 100 X | G10: Gram-positive rods, medium-sized, singly arranged | I10: MS
A11: 7
A12: 8
A13: 9
A14: 10
A15: 11
A16: 12
A17: 13
A18: 14
A19: 15
A20: 16
A21: 17
A22: 18
... A28: 24

Sheet 18_STABILITY
A1: 18 STABILITY
A4: S.No | B4: Sample ID | C4: Product Form | D4: Storage Temp / Condition | E4: Packaging / Container | F4: Study Start (Day 0) | G4: Day | H4: Date | I4: Time | J4: pH | K4: Appearance | L4: Odour | M4: Taste | N4: Texture | O4: CFU Ref | P4: Remarks | Q4: Recorded By

Sheet 19_ISOLATES
A1: 19 ISOLATE CHARACTERISATION
A2: One row per isolate. Colony morphology stays on 15_PLATING; staining stays on 17_MICROSCOPY against the same Isolate ID.
A4: S.No | B4: OB-EXP Ref | C4: Isolate ID | D4: Source Sample | E4: Plate Ref | F4: Catalase | G4: Motility | H4: Growth 50C | I4: Other Test - name and result | J4: Tentative ID | K4: Next Step / Sub-culture Plan | L4: Recorded By
A5: 1
A6: 2
A7: 3
A8: 4
A9: 5
A10: 6
A11: 7
A12: 8
A13: 9
A14: 10
A15: 11
A16: 12
... A20: 16

Sheet 20_DEVIATIONS
A1: 20 DEVIATIONS & GENERAL OBSERVATIONS
A2: Anything not covered by a numbered tab, plus every deviation from protocol for this batch.
A4: S.No | B4: Tab / Step | C4: Date | D4: Time | E4: Observation / Action Taken | F4: Data / Reading | G4: Deviation from Protocol | H4: Reason / Impact Assessment | I4: Approved By / Date | J4: Recorded By
A5: 1 | B5: Whole record | C5: 28-05-2026 | D5: — | E5: Batch migrated from the legacy 8-sheet template into the current 23-tab format. Legacy ID OBI-26-FER-003 recorded on 00_README. | F5: — | G5: Y - format migration | H5: No impact on data. Legacy workbook retained as the source record. | I5: LC / 28-05-2026 | J5: LC
A6: 2 | B6: 02 / 03 / 06 / 07 | C6: 28-05-2026 | D6: — | E6: No seed propagation stage exists. Inoculum was added directly to the batch flasks. Seed tabs marked N/A with reason. | F6: — | G6: N | H6: Legacy inoculum sheet Section E and F were blank throughout. | I6: LC / 28-05-2026 | J6: LC
A7: 3 | B7: 06 / 07 | C7: 28-05-2026 | D7: — | E7: Inoculum OD recorded as N/A. OD is not a valid cell-density measure in a curd or thawed-vial matrix at 600 nm, and no reading was taken. | F7: N/A | G7: N | H7: Correct measure is CFU/ml on MRS agar per OB-EXP-001. Not enumerated for this batch. | I7: LC / 28-05-2026 | J7: LC
A8: 4 | B8: 09_BATCH GROWTH LOG | C8: 28-05-2026 | D8: — | E8: Batch OD recorded as N/A at every timepoint, as in the legacy record. No spectrophotometer readings and no dilution factors exist. | F8: N/A | G8: N | H8: FER-004 onward record OD with a stated dilution factor. Without one a grain-slurry OD is uninterpretable, so none reconstructed. | I8: LC / 28-05-2026 | J8: LC
A9: 5 | B9: 13_DOWNSTREAM | C9: 28-05-2026 | D9: — | E9: Wet pellet derived by difference: 185 ml broth less 110 ml supernatant = 75 g. Dried to 4 g, so pellet dry matter 5.3%. | F9: 75 g wet / 4 g dry | G9: Y - derived, not weighed | H9: Legacy record left wet pellet blank. Derived, not a balance reading. Weigh directly on future batches. | I9: LC / 28-05-2026 | J9: LC
A10: 6 | B10: 13_DOWNSTREAM | C10: 28-05-2026 | D10: — | E10: Total Output of 114 g per flask is NOT a product yield. It is 110 ml of liquid added to 4 g of solid on the template 1 g per ml convention. | F10: 114 g | G10: Y - template convention defect | H10: Meaningful yield is the dried pellet: 4 g. Supernatant dissolved solids not measured. Affects FER-004 to -006 identically; revise at template level. | I10: LC / 28-05-2026 | J10: LC
A11: 7 | B11: All tabs | C11: 28-05-2026 | D11: — | E11: Equipment references corrected to ACE Biotechnology Department equipment IDs. The legacy record carried ACE-BT/INSTR/001, which is the instruction sheet document reference, not an equipment ID. | F11: See REF_EQUIPMENT | G11: Y - transcription error in legacy record | H11: Correct IDs: CO2 incubator ACE-BT/CO2INC/001, centrifuge ACE-BT/CENT/001, hot air oven ACE-BT/HAO/001, refrigerator ACE-BT/REF/001. | I11: LC / 28-05-2026 | J11: LC
A12: 8 | B12: 01 BATCH INFO | C12: 28-05-2026 | D12: — | E12: OB-EXP Ref on the legacy front sheet read FER-001. Corrected to FER-003. | F12: FER-003 | G12: Y - transcription error in legacy record | H12: Copy-paste carry-over from the FER-001 workbook. | I12: LC / 28-05-2026 | J12: LC
A13: 9 | B13: 10 / 11 / 16 / 17 / 18 / 19 | C13: 28-05-2026 | D13: — | E13: No standard curve, assay, CFU, microscopy, stability or isolate records exist for this batch. Tabs left blank rather than reconstructed. | F13: — | G13: N | H13: ANALYSIS will show pH only. | I13: LC / 28-05-2026 | J13: LC
A14: 10 | B14: 03_SEED INOCULATION | C14: 28-05-2026 | D14: — | E14: Inoculum source recorded as CRYO VIAL with culture ID RCB-001, but the cryovial ID, thaw method, thaw duration and post-thaw visual check were all left N/A in the legacy sheet. | F14: Not recorded | G14: Y - unrecoverable gap | H14: A vial ID is a physical label and cannot be reconstructed. Retrieve from the culture bank record for RCB-001, or this batch has no traceable link to its source stock. | I14: Pending | J14: LC
A15: 11 | B15: 08_BATCH INOCULATION | C15: 28-05-2026 | D15: — | E15: Inoculum figures conflict. The inoculum sheet records 5 ml dispensed across F1 and F2. The F1 growth sheet records 0.5% v/v (1 ml in 200 ml) and the F2 growth sheet records 1.0, which reads as 100% and cannot be correct. | F15: 5 ml vs 0.5% vs 1.0 | G15: Y - unresolved conflict | H15: If F1 received 1 ml and F2 2 ml the total is 3 ml, not 5 ml. This is an experimental variable, so no per-flask percentage has been asserted. Resolve before either flask is used in a comparison. | I15: Pending | J15: LC
A16: 12 | B16: 09 / 12 | C16: 28-05-2026 | D16: — | E16: Harvest final pH appears transposed between flasks. F1 growth log ends at 5.09 but the F1 harvest sheet records 5.12; F2 growth log ends at 5.12 but the F2 harvest sheet records 5.11. | F16: F1 5.09/5.12, F2 5.12/5.11 | G16: Y - conflict in legacy record | H16: Both sets retained as recorded on their own tabs. Verify against the ACE-BT/PHM/001 log. | I16: Pending | J16: LC
... A20: 16 | B20: Volume balance | C20: 28-05-2026 | D20: — | E20: Per flask: 200 ml media + inoculum, less 7 ml sampling, against 185 ml harvested. Loss approximately 9 ml (4%), consistent with FER-001. | F20: 201 -> 185 ml | G20: N | H20: Centrifugation of 185 ml took 4 h (13:00 to 17:00), which is long for this volume. Check the ACE-BT/CENT/001 log for run count. | I20: LC / 28-05-2026 | J20: LC

Sheet ANALYSIS
A1: ANALYSIS - DERIVED, DO NOT TYPE HERE
A4: Flask ID | B4: Log hr | C4: pH | D4: OD | E4: Anthrone Abs | F4: Total Carb (ug/ml) | G4: DNS Abs | H4: Reducing Sugar (ug/ml) | I4: Sample Vol (ml) | J4: NaOH N | K4: Titre 2 | L4: Titre 3 | M4: Concordant Mean (ml) | N4: Lactic Acid (% w/v)
A5: =IF('09_BATCH GROWTH LOG'!B5="","",'09_BATCH GROWTH LOG'!B5) -> F1 | B5: =IF('09_BATCH GROWTH LOG'!C5="","",'09_BATCH GROWTH LOG'!C5) -> 0 | C5: =IF('09_BATCH GROWTH LOG'!F5="","",'09_BATCH GROWTH LOG'!F5) -> 5.83 | D5: =IF('09_BATCH GROWTH LOG'!G5="","",'09_BATCH GROWTH LOG'!G5) -> NA | E5: =IFERROR(IF($A5="","",INDEX('11_ASSAY RESULTS'!$E$5:$E$44,MATCH($A5&"|"&$B5,'11_ASSAY RESULTS'!$P$5:$P$44,0))),"") | F5: =IFERROR(IF(OR(E5="",'10_STANDARD CURVES'!$B$15=""),"",(E5-'10_STANDARD CURVES'!$B$16)/'10_STANDARD CURVES'!$B$15*IF(IFERROR(INDEX('11_ASSAY RESULTS'!$F$5:$F$44,MATCH($A5&"|"&$B5,'11_ASSAY RESULTS'!$P$5:$P$44,0)),"")="",1,IFERROR(INDEX('11_ASSAY RESULTS'!$F$5:$F$44,MATCH($A5&"|"&$B5,'11_ASSAY RESULTS'!$P$5:$P$44,0)),""))),"") | G5: =IFERROR(IF($A5="","",INDEX('11_ASSAY RESULTS'!$G$5:$G$44,MATCH($A5&"|"&$B5,'11_ASSAY RESULTS'!$P$5:$P$44,0))),"") | H5: =IFERROR(IF(OR(G5="",'10_STANDARD CURVES'!$F$15=""),"",(G5-'10_STANDARD CURVES'!$F$16)/'10_STANDARD CURVES'!$F$15*IF(IFERROR(INDEX('11_ASSAY RESULTS'!$H$5:$H$44,MATCH($A5&"|"&$B5,'11_ASSAY RESULTS'!$P$5:$P$44,0)),"")="",1,IFERROR(INDEX('11_ASSAY RESULTS'!$H$5:$H$44,MATCH($A5&"|"&$B5,'11_ASSAY RESULTS'!$P$5:$P$44,0)),""))),"") | I5: =IFERROR(IF($A5="","",INDEX('11_ASSAY RESULTS'!$I$5:$I$44,MATCH($A5&"|"&$B5,'11_ASSAY RESULTS'!$P$5:$P$44,0))),"") | J5: =IFERROR(IF($A5="","",INDEX('11_ASSAY RESULTS'!$J$5:$J$44,MATCH($A5&"|"&$B5,'11_ASSAY RESULTS'!$P$5:$P$44,0))),"") | K5: =IFERROR(IF($A5="","",INDEX('11_ASSAY RESULTS'!$L$5:$L$44,MATCH($A5&"|"&$B5,'11_ASSAY RESULTS'!$P$5:$P$44,0))),"") | L5: =IFERROR(IF($A5="","",INDEX('11_ASSAY RESULTS'!$M$5:$M$44,MATCH($A5&"|"&$B5,'11_ASSAY RESULTS'!$P$5:$P$44,0))),"") | M5: =IFERROR(IF(AND(K5="",L5=""),"",AVERAGE(K5:L5)),"") | N5: =IFERROR(IF(OR(M5="",I5="",J5=""),"",M5*J5*0.09008/I5*100),"")
A6: =IF('09_BATCH GROWTH LOG'!B6="","",'09_BATCH GROWTH LOG'!B6) -> F1 | B6: =IF('09_BATCH GROWTH LOG'!C6="","",'09_BATCH GROWTH LOG'!C6) -> 6 | C6: =IF('09_BATCH GROWTH LOG'!F6="","",'09_BATCH GROWTH LOG'!F6) -> 5.55 | D6: =IF('09_BATCH GROWTH LOG'!G6="","",'09_BATCH GROWTH LOG'!G6) -> NA | E6: =IFERROR(IF($A6="","",INDEX('11_ASSAY RESULTS'!$E$5:$E$44,MATCH($A6&"|"&$B6,'11_ASSAY RESULTS'!$P$5:$P$44,0))),"") | F6: =IFERROR(IF(OR(E6="",'10_STANDARD CURVES'!$B$15=""),"",(E6-'10_STANDARD CURVES'!$B$16)/'10_STANDARD CURVES'!$B$15*IF(IFERROR(INDEX('11_ASSAY RESULTS'!$F$5:$F$44,MATCH($A6&"|"&$B6,'11_ASSAY RESULTS'!$P$5:$P$44,0)),"")="",1,IFERROR(INDEX('11_ASSAY RESULTS'!$F$5:$F$44,MATCH($A6&"|"&$B6,'11_ASSAY RESULTS'!$P$5:$P$44,0)),""))),"") | G6: =IFERROR(IF($A6="","",INDEX('11_ASSAY RESULTS'!$G$5:$G$44,MATCH($A6&"|"&$B6,'11_ASSAY RESULTS'!$P$5:$P$44,0))),"") | H6: =IFERROR(IF(OR(G6="",'10_STANDARD CURVES'!$F$15=""),"",(G6-'10_STANDARD CURVES'!$F$16)/'10_STANDARD CURVES'!$F$15*IF(IFERROR(INDEX('11_ASSAY RESULTS'!$H$5:$H$44,MATCH($A6&"|"&$B6,'11_ASSAY RESULTS'!$P$5:$P$44,0)),"")="",1,IFERROR(INDEX('11_ASSAY RESULTS'!$H$5:$H$44,MATCH($A6&"|"&$B6,'11_ASSAY RESULTS'!$P$5:$P$44,0)),""))),"") | I6: =IFERROR(IF($A6="","",INDEX('11_ASSAY RESULTS'!$I$5:$I$44,MATCH($A6&"|"&$B6,'11_ASSAY RESULTS'!$P$5:$P$44,0))),"") | J6: =IFERROR(IF($A6="","",INDEX('11_ASSAY RESULTS'!$J$5:$J$44,MATCH($A6&"|"&$B6,'11_ASSAY RESULTS'!$P$5:$P$44,0))),"") | K6: =IFERROR(IF($A6="","",INDEX('11_ASSAY RESULTS'!$L$5:$L$44,MATCH($A6&"|"&$B6,'11_ASSAY RESULTS'!$P$5:$P$44,0))),"") | L6: =IFERROR(IF($A6="","",INDEX('11_ASSAY RESULTS'!$M$5:$M$44,MATCH($A6&"|"&$B6,'11_ASSAY RESULTS'!$P$5:$P$44,0))),"") | M6: =IFERROR(IF(AND(K6="",L6=""),"",AVERAGE(K6:L6)),"") | N6: =IFERROR(IF(OR(M6="",I6="",J6=""),"",M6*J6*0.09008/I6*100),"")
A7: =IF('09_BATCH GROWTH LOG'!B7="","",'09_BATCH GROWTH LOG'!B7) -> F1 | B7: =IF('09_BATCH GROWTH LOG'!C7="","",'09_BATCH GROWTH LOG'!C7) -> 12 | C7: =IF('09_BATCH GROWTH LOG'!F7="","",'09_BATCH GROWTH LOG'!F7) -> 5.35 | D7: =IF('09_BATCH GROWTH LOG'!G7="","",'09_BATCH GROWTH LOG'!G7) -> NA | E7: =IFERROR(IF($A7="","",INDEX('11_ASSAY RESULTS'!$E$5:$E$44,MATCH($A7&"|"&$B7,'11_ASSAY RESULTS'!$P$5:$P$44,0))),"") | F7: =IFERROR(IF(OR(E7="",'10_STANDARD CURVES'!$B$15=""),"",(E7-'10_STANDARD CURVES'!$B$16)/'10_STANDARD CURVES'!$B$15*IF(IFERROR(INDEX('11_ASSAY RESULTS'!$F$5:$F$44,MATCH($A7&"|"&$B7,'11_ASSAY RESULTS'!$P$5:$P$44,0)),"")="",1,IFERROR(INDEX('11_ASSAY RESULTS'!$F$5:$F$44,MATCH($A7&"|"&$B7,'11_ASSAY RESULTS'!$P$5:$P$44,0)),""))),"") | G7: =IFERROR(IF($A7="","",INDEX('11_ASSAY RESULTS'!$G$5:$G$44,MATCH($A7&"|"&$B7,'11_ASSAY RESULTS'!$P$5:$P$44,0))),"") | H7: =IFERROR(IF(OR(G7="",'10_STANDARD CURVES'!$F$15=""),"",(G7-'10_STANDARD CURVES'!$F$16)/'10_STANDARD CURVES'!$F$15*IF(IFERROR(INDEX('11_ASSAY RESULTS'!$H$5:$H$44,MATCH($A7&"|"&$B7,'11_ASSAY RESULTS'!$P$5:$P$44,0)),"")="",1,IFERROR(INDEX('11_ASSAY RESULTS'!$H$5:$H$44,MATCH($A7&"|"&$B7,'11_ASSAY RESULTS'!$P$5:$P$44,0)),""))),"") | I7: =IFERROR(IF($A7="","",INDEX('11_ASSAY RESULTS'!$I$5:$I$44,MATCH($A7&"|"&$B7,'11_ASSAY RESULTS'!$P$5:$P$44,0))),"") | J7: =IFERROR(IF($A7="","",INDEX('11_ASSAY RESULTS'!$J$5:$J$44,MATCH($A7&"|"&$B7,'11_ASSAY RESULTS'!$P$5:$P$44,0))),"") | K7: =IFERROR(IF($A7="","",INDEX('11_ASSAY RESULTS'!$L$5:$L$44,MATCH($A7&"|"&$B7,'11_ASSAY RESULTS'!$P$5:$P$44,0))),"") | L7: =IFERROR(IF($A7="","",INDEX('11_ASSAY RESULTS'!$M$5:$M$44,MATCH($A7&"|"&$B7,'11_ASSAY RESULTS'!$P$5:$P$44,0))),"") | M7: =IFERROR(IF(AND(K7="",L7=""),"",AVERAGE(K7:L7)),"") | N7: =IFERROR(IF(OR(M7="",I7="",J7=""),"",M7*J7*0.09008/I7*100),"")
A8: =IF('09_BATCH GROWTH LOG'!B8="","",'09_BATCH GROWTH LOG'!B8) -> F1 | B8: =IF('09_BATCH GROWTH LOG'!C8="","",'09_BATCH GROWTH LOG'!C8) -> 24 | C8: =IF('09_BATCH GROWTH LOG'!F8="","",'09_BATCH GROWTH LOG'!F8) -> 5.17 | D8: =IF('09_BATCH GROWTH LOG'!G8="","",'09_BATCH GROWTH LOG'!G8) -> NA | E8: =IFERROR(IF($A8="","",INDEX('11_ASSAY RESULTS'!$E$5:$E$44,MATCH($A8&"|"&$B8,'11_ASSAY RESULTS'!$P$5:$P$44,0))),"") | F8: =IFERROR(IF(OR(E8="",'10_STANDARD CURVES'!$B$15=""),"",(E8-'10_STANDARD CURVES'!$B$16)/'10_STANDARD CURVES'!$B$15*IF(IFERROR(INDEX('11_ASSAY RESULTS'!$F$5:$F$44,MATCH($A8&"|"&$B8,'11_ASSAY RESULTS'!$P$5:$P$44,0)),"")="",1,IFERROR(INDEX('11_ASSAY RESULTS'!$F$5:$F$44,MATCH($A8&"|"&$B8,'11_ASSAY RESULTS'!$P$5:$P$44,0)),""))),"") | G8: =IFERROR(IF($A8="","",INDEX('11_ASSAY RESULTS'!$G$5:$G$44,MATCH($A8&"|"&$B8,'11_ASSAY RESULTS'!$P$5:$P$44,0))),"") | H8: =IFERROR(IF(OR(G8="",'10_STANDARD CURVES'!$F$15=""),"",(G8-'10_STANDARD CURVES'!$F$16)/'10_STANDARD CURVES'!$F$15*IF(IFERROR(INDEX('11_ASSAY RESULTS'!$H$5:$H$44,MATCH($A8&"|"&$B8,'11_ASSAY RESULTS'!$P$5:$P$44,0)),"")="",1,IFERROR(INDEX('11_ASSAY RESULTS'!$H$5:$H$44,MATCH($A8&"|"&$B8,'11_ASSAY RESULTS'!$P$5:$P$44,0)),""))),"") | I8: =IFERROR(IF($A8="","",INDEX('11_ASSAY RESULTS'!$I$5:$I$44,MATCH($A8&"|"&$B8,'11_ASSAY RESULTS'!$P$5:$P$44,0))),"") | J8: =IFERROR(IF($A8="","",INDEX('11_ASSAY RESULTS'!$J$5:$J$44,MATCH($A8&"|"&$B8,'11_ASSAY RESULTS'!$P$5:$P$44,0))),"") | K8: =IFERROR(IF($A8="","",INDEX('11_ASSAY RESULTS'!$L$5:$L$44,MATCH($A8&"|"&$B8,'11_ASSAY RESULTS'!$P$5:$P$44,0))),"") | L8: =IFERROR(IF($A8="","",INDEX('11_ASSAY RESULTS'!$M$5:$M$44,MATCH($A8&"|"&$B8,'11_ASSAY RESULTS'!$P$5:$P$44,0))),"") | M8: =IFERROR(IF(AND(K8="",L8=""),"",AVERAGE(K8:L8)),"") | N8: =IFERROR(IF(OR(M8="",I8="",J8=""),"",M8*J8*0.09008/I8*100),"")
A9: =IF('09_BATCH GROWTH LOG'!B9="","",'09_BATCH GROWTH LOG'!B9) -> F1 | B9: =IF('09_BATCH GROWTH LOG'!C9="","",'09_BATCH GROWTH LOG'!C9) -> 30 | C9: =IF('09_BATCH GROWTH LOG'!F9="","",'09_BATCH GROWTH LOG'!F9) -> 5.13 | D9: =IF('09_BATCH GROWTH LOG'!G9="","",'09_BATCH GROWTH LOG'!G9) -> NA | E9: =IFERROR(IF($A9="","",INDEX('11_ASSAY RESULTS'!$E$5:$E$44,MATCH($A9&"|"&$B9,'11_ASSAY RESULTS'!$P$5:$P$44,0))),"") | F9: =IFERROR(IF(OR(E9="",'10_STANDARD CURVES'!$B$15=""),"",(E9-'10_STANDARD CURVES'!$B$16)/'10_STANDARD CURVES'!$B$15*IF(IFERROR(INDEX('11_ASSAY RESULTS'!$F$5:$F$44,MATCH($A9&"|"&$B9,'11_ASSAY RESULTS'!$P$5:$P$44,0)),"")="",1,IFERROR(INDEX('11_ASSAY RESULTS'!$F$5:$F$44,MATCH($A9&"|"&$B9,'11_ASSAY RESULTS'!$P$5:$P$44,0)),""))),"") | G9: =IFERROR(IF($A9="","",INDEX('11_ASSAY RESULTS'!$G$5:$G$44,MATCH($A9&"|"&$B9,'11_ASSAY RESULTS'!$P$5:$P$44,0))),"") | H9: =IFERROR(IF(OR(G9="",'10_STANDARD CURVES'!$F$15=""),"",(G9-'10_STANDARD CURVES'!$F$16)/'10_STANDARD CURVES'!$F$15*IF(IFERROR(INDEX('11_ASSAY RESULTS'!$H$5:$H$44,MATCH($A9&"|"&$B9,'11_ASSAY RESULTS'!$P$5:$P$44,0)),"")="",1,IFERROR(INDEX('11_ASSAY RESULTS'!$H$5:$H$44,MATCH($A9&"|"&$B9,'11_ASSAY RESULTS'!$P$5:$P$44,0)),""))),"") | I9: =IFERROR(IF($A9="","",INDEX('11_ASSAY RESULTS'!$I$5:$I$44,MATCH($A9&"|"&$B9,'11_ASSAY RESULTS'!$P$5:$P$44,0))),"") | J9: =IFERROR(IF($A9="","",INDEX('11_ASSAY RESULTS'!$J$5:$J$44,MATCH($A9&"|"&$B9,'11_ASSAY RESULTS'!$P$5:$P$44,0))),"") | K9: =IFERROR(IF($A9="","",INDEX('11_ASSAY RESULTS'!$L$5:$L$44,MATCH($A9&"|"&$B9,'11_ASSAY RESULTS'!$P$5:$P$44,0))),"") | L9: =IFERROR(IF($A9="","",INDEX('11_ASSAY RESULTS'!$M$5:$M$44,MATCH($A9&"|"&$B9,'11_ASSAY RESULTS'!$P$5:$P$44,0))),"") | M9: =IFERROR(IF(AND(K9="",L9=""),"",AVERAGE(K9:L9)),"") | N9: =IFERROR(IF(OR(M9="",I9="",J9=""),"",M9*J9*0.09008/I9*100),"")
A10: =IF('09_BATCH GROWTH LOG'!B10="","",'09_BATCH GROWTH LOG'!B10) -> F1 | B10: =IF('09_BATCH GROWTH LOG'!C10="","",'09_BATCH GROWTH LOG'!C10) -> 36 | C10: =IF('09_BATCH GROWTH LOG'!F10="","",'09_BATCH GROWTH LOG'!F10) -> 5.11 | D10: =IF('09_BATCH GROWTH LOG'!G10="","",'09_BATCH GROWTH LOG'!G10) -> NA | E10: =IFERROR(IF($A10="","",INDEX('11_ASSAY RESULTS'!$E$5:$E$44,MATCH($A10&"|"&$B10,'11_ASSAY RESULTS'!$P$5:$P$44,0))),"") | F10: =IFERROR(IF(OR(E10="",'10_STANDARD CURVES'!$B$15=""),"",(E10-'10_STANDARD CURVES'!$B$16)/'10_STANDARD CURVES'!$B$15*IF(IFERROR(INDEX('11_ASSAY RESULTS'!$F$5:$F$44,MATCH($A10&"|"&$B10,'11_ASSAY RESULTS'!$P$5:$P$44,0)),"")="",1,IFERROR(INDEX('11_ASSAY RESULTS'!$F$5:$F$44,MATCH($A10&"|"&$B10,'11_ASSAY RESULTS'!$P$5:$P$44,0)),""))),"") | G10: =IFERROR(IF($A10="","",INDEX('11_ASSAY RESULTS'!$G$5:$G$44,MATCH($A10&"|"&$B10,'11_ASSAY RESULTS'!$P$5:$P$44,0))),"") | I10: =IFERROR(IF($A10="","",INDEX('11_ASSAY RESULTS'!$I$5:$I$44,MATCH($A10&"|"&$B10,'11_ASSAY RESULTS'!$P$5:$P$44,0))),"") | J10: =IFERROR(IF($A10="","",INDEX('11_ASSAY RESULTS'!$J$5:$J$44,MATCH($A10&"|"&$B10,'11_ASSAY RESULTS'!$P$5:$P$44,0))),"") | K10: =IFERROR(IF($A10="","",INDEX('11_ASSAY RESULTS'!$L$5:$L$44,MATCH($A10&"|"&$B10,'11_ASSAY RESULTS'!$P$5:$P$44,0))),"") | L10: =IFERROR(IF($A10="","",INDEX('11_ASSAY RESULTS'!$M$5:$M$44,MATCH($A10&"|"&$B10,'11_ASSAY RESULTS'!$P$5:$P$44,0))),"") | M10: =IFERROR(IF(AND(K10="",L10=""),"",AVERAGE(K10:L10)),"") | N10: =IFERROR(IF(OR(M10="",I10="",J10=""),"",M10*J10*0.09008/I10*100),"")
A11: =IF('09_BATCH GROWTH LOG'!B11="","",'09_BATCH GROWTH LOG'!B11) -> F1 | B11: =IF('09_BATCH GROWTH LOG'!C11="","",'09_BATCH GROWTH LOG'!C11) -> 48 | C11: =IF('09_BATCH GROWTH LOG'!F11="","",'09_BATCH GROWTH LOG'!F11) -> 5.09 | D11: =IF('09_BATCH GROWTH LOG'!G11="","",'09_BATCH GROWTH LOG'!G11) -> NA | E11: =IFERROR(IF($A11="","",INDEX('11_ASSAY RESULTS'!$E$5:$E$44,MATCH($A11&"|"&$B11,'11_ASSAY RESULTS'!$P$5:$P$44,0))),"") | F11: =IFERROR(IF(OR(E11="",'10_STANDARD CURVES'!$B$15=""),"",(E11-'10_STANDARD CURVES'!$B$16)/'10_STANDARD CURVES'!$B$15*IF(IFERROR(INDEX('11_ASSAY RESULTS'!$F$5:$F$44,MATCH($A11&"|"&$B11,'11_ASSAY RESULTS'!$P$5:$P$44,0)),"")="",1,IFERROR(INDEX('11_ASSAY RESULTS'!$F$5:$F$44,MATCH($A11&"|"&$B11,'11_ASSAY RESULTS'!$P$5:$P$44,0)),""))),"") | G11: =IFERROR(IF($A11="","",INDEX('11_ASSAY RESULTS'!$G$5:$G$44,MATCH($A11&"|"&$B11,'11_ASSAY RESULTS'!$P$5:$P$44,0))),"") | H11: =IFERROR(IF(OR(G11="",'10_STANDARD CURVES'!$F$15=""),"",(G11-'10_STANDARD CURVES'!$F$16)/'10_STANDARD CURVES'!$F$15*IF(IFERROR(INDEX('11_ASSAY RESULTS'!$H$5:$H$44,MATCH($A11&"|"&$B11,'11_ASSAY RESULTS'!$P$5:$P$44,0)),"")="",1,IFERROR(INDEX('11_ASSAY RESULTS'!$H$5:$H$44,MATCH($A11&"|"&$B11,'11_ASSAY RESULTS'!$P$5:$P$44,0)),""))),"") | I11: =IFERROR(IF($A11="","",INDEX('11_ASSAY RESULTS'!$I$5:$I$44,MATCH($A11&"|"&$B11,'11_ASSAY RESULTS'!$P$5:$P$44,0))),"") | J11: =IFERROR(IF($A11="","",INDEX('11_ASSAY RESULTS'!$J$5:$J$44,MATCH($A11&"|"&$B11,'11_ASSAY RESULTS'!$P$5:$P$44,0))),"") | K11: =IFERROR(IF($A11="","",INDEX('11_ASSAY RESULTS'!$L$5:$L$44,MATCH($A11&"|"&$B11,'11_ASSAY RESULTS'!$P$5:$P$44,0))),"") | L11: =IFERROR(IF($A11="","",INDEX('11_ASSAY RESULTS'!$M$5:$M$44,MATCH($A11&"|"&$B11,'11_ASSAY RESULTS'!$P$5:$P$44,0))),"") | M11: =IFERROR(IF(AND(K11="",L11=""),"",AVERAGE(K11:L11)),"") | N11: =IFERROR(IF(OR(M11="",I11="",J11=""),"",M11*J11*0.09008/I11*100),"")
A12: =IF('09_BATCH GROWTH LOG'!B12="","",'09_BATCH GROWTH LOG'!B12) -> F2 | B12: =IF('09_BATCH GROWTH LOG'!C12="","",'09_BATCH GROWTH LOG'!C12) -> 0 | C12: =IF('09_BATCH GROWTH LOG'!F12="","",'09_BATCH GROWTH LOG'!F12) -> 5.7 | D12: =IF('09_BATCH GROWTH LOG'!G12="","",'09_BATCH GROWTH LOG'!G12) -> NA | E12: =IFERROR(IF($A12="","",INDEX('11_ASSAY RESULTS'!$E$5:$E$44,MATCH($A12&"|"&$B12,'11_ASSAY RESULTS'!$P$5:$P$44,0))),"") | F12: =IFERROR(IF(OR(E12="",'10_STANDARD CURVES'!$B$15=""),"",(E12-'10_STANDARD CURVES'!$B$16)/'10_STANDARD CURVES'!$B$15*IF(IFERROR(INDEX('11_ASSAY RESULTS'!$F$5:$F$44,MATCH($A12&"|"&$B12,'11_ASSAY RESULTS'!$P$5:$P$44,0)),"")="",1,IFERROR(INDEX('11_ASSAY RESULTS'!$F$5:$F$44,MATCH($A12&"|"&$B12,'11_ASSAY RESULTS'!$P$5:$P$44,0)),""))),"") | G12: =IFERROR(IF($A12="","",INDEX('11_ASSAY RESULTS'!$G$5:$G$44,MATCH($A12&"|"&$B12,'11_ASSAY RESULTS'!$P$5:$P$44,0))),"") | H12: =IFERROR(IF(OR(G12="",'10_STANDARD CURVES'!$F$15=""),"",(G12-'10_STANDARD CURVES'!$F$16)/'10_STANDARD CURVES'!$F$15*IF(IFERROR(INDEX('11_ASSAY RESULTS'!$H$5:$H$44,MATCH($A12&"|"&$B12,'11_ASSAY RESULTS'!$P$5:$P$44,0)),"")="",1,IFERROR(INDEX('11_ASSAY RESULTS'!$H$5:$H$44,MATCH($A12&"|"&$B12,'11_ASSAY RESULTS'!$P$5:$P$44,0)),""))),"") | I12: =IFERROR(IF($A12="","",INDEX('11_ASSAY RESULTS'!$I$5:$I$44,MATCH($A12&"|"&$B12,'11_ASSAY RESULTS'!$P$5:$P$44,0))),"") | J12: =IFERROR(IF($A12="","",INDEX('11_ASSAY RESULTS'!$J$5:$J$44,MATCH($A12&"|"&$B12,'11_ASSAY RESULTS'!$P$5:$P$44,0))),"") | K12: =IFERROR(IF($A12="","",INDEX('11_ASSAY RESULTS'!$L$5:$L$44,MATCH($A12&"|"&$B12,'11_ASSAY RESULTS'!$P$5:$P$44,0))),"") | L12: =IFERROR(IF($A12="","",INDEX('11_ASSAY RESULTS'!$M$5:$M$44,MATCH($A12&"|"&$B12,'11_ASSAY RESULTS'!$P$5:$P$44,0))),"") | M12: =IFERROR(IF(AND(K12="",L12=""),"",AVERAGE(K12:L12)),"") | N12: =IFERROR(IF(OR(M12="",I12="",J12=""),"",M12*J12*0.09008/I12*100),"")
A13: =IF('09_BATCH GROWTH LOG'!B13="","",'09_BATCH GROWTH LOG'!B13) -> F2 | B13: =IF('09_BATCH GROWTH LOG'!C13="","",'09_BATCH GROWTH LOG'!C13) -> 6 | C13: =IF('09_BATCH GROWTH LOG'!F13="","",'09_BATCH GROWTH LOG'!F13) -> 5.58 | D13: =IF('09_BATCH GROWTH LOG'!G13="","",'09_BATCH GROWTH LOG'!G13) -> NA | E13: =IFERROR(IF($A13="","",INDEX('11_ASSAY RESULTS'!$E$5:$E$44,MATCH($A13&"|"&$B13,'11_ASSAY RESULTS'!$P$5:$P$44,0))),"") | F13: =IFERROR(IF(OR(E13="",'10_STANDARD CURVES'!$B$15=""),"",(E13-'10_STANDARD CURVES'!$B$16)/'10_STANDARD CURVES'!$B$15*IF(IFERROR(INDEX('11_ASSAY RESULTS'!$F$5:$F$44,MATCH($A13&"|"&$B13,'11_ASSAY RESULTS'!$P$5:$P$44,0)),"")="",1,IFERROR(INDEX('11_ASSAY RESULTS'!$F$5:$F$44,MATCH($A13&"|"&$B13,'11_ASSAY RESULTS'!$P$5:$P$44,0)),""))),"") | G13: =IFERROR(IF($A13="","",INDEX('11_ASSAY RESULTS'!$G$5:$G$44,MATCH($A13&"|"&$B13,'11_ASSAY RESULTS'!$P$5:$P$44,0))),"") | H13: =IFERROR(IF(OR(G13="",'10_STANDARD CURVES'!$F$15=""),"",(G13-'10_STANDARD CURVES'!$F$16)/'10_STANDARD CURVES'!$F$15*IF(IFERROR(INDEX('11_ASSAY RESULTS'!$H$5:$H$44,MATCH($A13&"|"&$B13,'11_ASSAY RESULTS'!$P$5:$P$44,0)),"")="",1,IFERROR(INDEX('11_ASSAY RESULTS'!$H$5:$H$44,MATCH($A13&"|"&$B13,'11_ASSAY RESULTS'!$P$5:$P$44,0)),""))),"") | I13: =IFERROR(IF($A13="","",INDEX('11_ASSAY RESULTS'!$I$5:$I$44,MATCH($A13&"|"&$B13,'11_ASSAY RESULTS'!$P$5:$P$44,0))),"") | J13: =IFERROR(IF($A13="","",INDEX('11_ASSAY RESULTS'!$J$5:$J$44,MATCH($A13&"|"&$B13,'11_ASSAY RESULTS'!$P$5:$P$44,0))),"") | K13: =IFERROR(IF($A13="","",INDEX('11_ASSAY RESULTS'!$L$5:$L$44,MATCH($A13&"|"&$B13,'11_ASSAY RESULTS'!$P$5:$P$44,0))),"") | L13: =IFERROR(IF($A13="","",INDEX('11_ASSAY RESULTS'!$M$5:$M$44,MATCH($A13&"|"&$B13,'11_ASSAY RESULTS'!$P$5:$P$44,0))),"") | M13: =IFERROR(IF(AND(K13="",L13=""),"",AVERAGE(K13:L13)),"") | N13: =IFERROR(IF(OR(M13="",I13="",J13=""),"",M13*J13*0.09008/I13*100),"")
A14: =IF('09_BATCH GROWTH LOG'!B14="","",'09_BATCH GROWTH LOG'!B14) -> F2 | B14: =IF('09_BATCH GROWTH LOG'!C14="","",'09_BATCH GROWTH LOG'!C14) -> 12 | C14: =IF('09_BATCH GROWTH LOG'!F14="","",'09_BATCH GROWTH LOG'!F14) -> 5.48 | D14: =IF('09_BATCH GROWTH LOG'!G14="","",'09_BATCH GROWTH LOG'!G14) -> NA | E14: =IFERROR(IF($A14="","",INDEX('11_ASSAY RESULTS'!$E$5:$E$44,MATCH($A14&"|"&$B14,'11_ASSAY RESULTS'!$P$5:$P$44,0))),"") | F14: =IFERROR(IF(OR(E14="",'10_STANDARD CURVES'!$B$15=""),"",(E14-'10_STANDARD CURVES'!$B$16)/'10_STANDARD CURVES'!$B$15*IF(IFERROR(INDEX('11_ASSAY RESULTS'!$F$5:$F$44,MATCH($A14&"|"&$B14,'11_ASSAY RESULTS'!$P$5:$P$44,0)),"")="",1,IFERROR(INDEX('11_ASSAY RESULTS'!$F$5:$F$44,MATCH($A14&"|"&$B14,'11_ASSAY RESULTS'!$P$5:$P$44,0)),""))),"") | G14: =IFERROR(IF($A14="","",INDEX('11_ASSAY RESULTS'!$G$5:$G$44,MATCH($A14&"|"&$B14,'11_ASSAY RESULTS'!$P$5:$P$44,0))),"") | H14: =IFERROR(IF(OR(G14="",'10_STANDARD CURVES'!$F$15=""),"",(G14-'10_STANDARD CURVES'!$F$16)/'10_STANDARD CURVES'!$F$15*IF(IFERROR(INDEX('11_ASSAY RESULTS'!$H$5:$H$44,MATCH($A14&"|"&$B14,'11_ASSAY RESULTS'!$P$5:$P$44,0)),"")="",1,IFERROR(INDEX('11_ASSAY RESULTS'!$H$5:$H$44,MATCH($A14&"|"&$B14,'11_ASSAY RESULTS'!$P$5:$P$44,0)),""))),"") | I14: =IFERROR(IF($A14="","",INDEX('11_ASSAY RESULTS'!$I$5:$I$44,MATCH($A14&"|"&$B14,'11_ASSAY RESULTS'!$P$5:$P$44,0))),"") | J14: =IFERROR(IF($A14="","",INDEX('11_ASSAY RESULTS'!$J$5:$J$44,MATCH($A14&"|"&$B14,'11_ASSAY RESULTS'!$P$5:$P$44,0))),"") | K14: =IFERROR(IF($A14="","",INDEX('11_ASSAY RESULTS'!$L$5:$L$44,MATCH($A14&"|"&$B14,'11_ASSAY RESULTS'!$P$5:$P$44,0))),"") | L14: =IFERROR(IF($A14="","",INDEX('11_ASSAY RESULTS'!$M$5:$M$44,MATCH($A14&"|"&$B14,'11_ASSAY RESULTS'!$P$5:$P$44,0))),"") | M14: =IFERROR(IF(AND(K14="",L14=""),"",AVERAGE(K14:L14)),"") | N14: =IFERROR(IF(OR(M14="",I14="",J14=""),"",M14*J14*0.09008/I14*100),"")
A15: =IF('09_BATCH GROWTH LOG'!B15="","",'09_BATCH GROWTH LOG'!B15) -> F2 | B15: =IF('09_BATCH GROWTH LOG'!C15="","",'09_BATCH GROWTH LOG'!C15) -> 24 | C15: =IF('09_BATCH GROWTH LOG'!F15="","",'09_BATCH GROWTH LOG'!F15) -> 5.4 | D15: =IF('09_BATCH GROWTH LOG'!G15="","",'09_BATCH GROWTH LOG'!G15) -> NA | E15: =IFERROR(IF($A15="","",INDEX('11_ASSAY RESULTS'!$E$5:$E$44,MATCH($A15&"|"&$B15,'11_ASSAY RESULTS'!$P$5:$P$44,0))),"") | F15: =IFERROR(IF(OR(E15="",'10_STANDARD CURVES'!$B$15=""),"",(E15-'10_STANDARD CURVES'!$B$16)/'10_STANDARD CURVES'!$B$15*IF(IFERROR(INDEX('11_ASSAY RESULTS'!$F$5:$F$44,MATCH($A15&"|"&$B15,'11_ASSAY RESULTS'!$P$5:$P$44,0)),"")="",1,IFERROR(INDEX('11_ASSAY RESULTS'!$F$5:$F$44,MATCH($A15&"|"&$B15,'11_ASSAY RESULTS'!$P$5:$P$44,0)),""))),"") | G15: =IFERROR(IF($A15="","",INDEX('11_ASSAY RESULTS'!$G$5:$G$44,MATCH($A15&"|"&$B15,'11_ASSAY RESULTS'!$P$5:$P$44,0))),"") | H15: =IFERROR(IF(OR(G15="",'10_STANDARD CURVES'!$F$15=""),"",(G15-'10_STANDARD CURVES'!$F$16)/'10_STANDARD CURVES'!$F$15*IF(IFERROR(INDEX('11_ASSAY RESULTS'!$H$5:$H$44,MATCH($A15&"|"&$B15,'11_ASSAY RESULTS'!$P$5:$P$44,0)),"")="",1,IFERROR(INDEX('11_ASSAY RESULTS'!$H$5:$H$44,MATCH($A15&"|"&$B15,'11_ASSAY RESULTS'!$P$5:$P$44,0)),""))),"") | I15: =IFERROR(IF($A15="","",INDEX('11_ASSAY RESULTS'!$I$5:$I$44,MATCH($A15&"|"&$B15,'11_ASSAY RESULTS'!$P$5:$P$44,0))),"") | J15: =IFERROR(IF($A15="","",INDEX('11_ASSAY RESULTS'!$J$5:$J$44,MATCH($A15&"|"&$B15,'11_ASSAY RESULTS'!$P$5:$P$44,0))),"") | K15: =IFERROR(IF($A15="","",INDEX('11_ASSAY RESULTS'!$L$5:$L$44,MATCH($A15&"|"&$B15,'11_ASSAY RESULTS'!$P$5:$P$44,0))),"") | L15: =IFERROR(IF($A15="","",INDEX('11_ASSAY RESULTS'!$M$5:$M$44,MATCH($A15&"|"&$B15,'11_ASSAY RESULTS'!$P$5:$P$44,0))),"") | M15: =IFERROR(IF(AND(K15="",L15=""),"",AVERAGE(K15:L15)),"") | N15: =IFERROR(IF(OR(M15="",I15="",J15=""),"",M15*J15*0.09008/I15*100),"")
A16: =IF('09_BATCH GROWTH LOG'!B16="","",'09_BATCH GROWTH LOG'!B16) -> F2 | B16: =IF('09_BATCH GROWTH LOG'!C16="","",'09_BATCH GROWTH LOG'!C16) -> 30 | C16: =IF('09_BATCH GROWTH LOG'!F16="","",'09_BATCH GROWTH LOG'!F16) -> 5.3 | D16: =IF('09_BATCH GROWTH LOG'!G16="","",'09_BATCH GROWTH LOG'!G16) -> NA | E16: =IFERROR(IF($A16="","",INDEX('11_ASSAY RESULTS'!$E$5:$E$44,MATCH($A16&"|"&$B16,'11_ASSAY RESULTS'!$P$5:$P$44,0))),"") | F16: =IFERROR(IF(OR(E16="",'10_STANDARD CURVES'!$B$15=""),"",(E16-'10_STANDARD CURVES'!$B$16)/'10_STANDARD CURVES'!$B$15*IF(IFERROR(INDEX('11_ASSAY RESULTS'!$F$5:$F$44,MATCH($A16&"|"&$B16,'11_ASSAY RESULTS'!$P$5:$P$44,0)),"")="",1,IFERROR(INDEX('11_ASSAY RESULTS'!$F$5:$F$44,MATCH($A16&"|"&$B16,'11_ASSAY RESULTS'!$P$5:$P$44,0)),""))),"") | G16: =IFERROR(IF($A16="","",INDEX('11_ASSAY RESULTS'!$G$5:$G$44,MATCH($A16&"|"&$B16,'11_ASSAY RESULTS'!$P$5:$P$44,0))),"") | H16: =IFERROR(IF(OR(G16="",'10_STANDARD CURVES'!$F$15=""),"",(G16-'10_STANDARD CURVES'!$F$16)/'10_STANDARD CURVES'!$F$15*IF(IFERROR(INDEX('11_ASSAY RESULTS'!$H$5:$H$44,MATCH($A16&"|"&$B16,'11_ASSAY RESULTS'!$P$5:$P$44,0)),"")="",1,IFERROR(INDEX('11_ASSAY RESULTS'!$H$5:$H$44,MATCH($A16&"|"&$B16,'11_ASSAY RESULTS'!$P$5:$P$44,0)),""))),"") | I16: =IFERROR(IF($A16="","",INDEX('11_ASSAY RESULTS'!$I$5:$I$44,MATCH($A16&"|"&$B16,'11_ASSAY RESULTS'!$P$5:$P$44,0))),"") | J16: =IFERROR(IF($A16="","",INDEX('11_ASSAY RESULTS'!$J$5:$J$44,MATCH($A16&"|"&$B16,'11_ASSAY RESULTS'!$P$5:$P$44,0))),"") | K16: =IFERROR(IF($A16="","",INDEX('11_ASSAY RESULTS'!$L$5:$L$44,MATCH($A16&"|"&$B16,'11_ASSAY RESULTS'!$P$5:$P$44,0))),"") | L16: =IFERROR(IF($A16="","",INDEX('11_ASSAY RESULTS'!$M$5:$M$44,MATCH($A16&"|"&$B16,'11_ASSAY RESULTS'!$P$5:$P$44,0))),"") | M16: =IFERROR(IF(AND(K16="",L16=""),"",AVERAGE(K16:L16)),"") | N16: =IFERROR(IF(OR(M16="",I16="",J16=""),"",M16*J16*0.09008/I16*100),"")
A17: =IF('09_BATCH GROWTH LOG'!B17="","",'09_BATCH GROWTH LOG'!B17) -> F2 | B17: =IF('09_BATCH GROWTH LOG'!C17="","",'09_BATCH GROWTH LOG'!C17) -> 36 | C17: =IF('09_BATCH GROWTH LOG'!F17="","",'09_BATCH GROWTH LOG'!F17) -> 5.2 | D17: =IF('09_BATCH GROWTH LOG'!G17="","",'09_BATCH GROWTH LOG'!G17) -> NA | E17: =IFERROR(IF($A17="","",INDEX('11_ASSAY RESULTS'!$E$5:$E$44,MATCH($A17&"|"&$B17,'11_ASSAY RESULTS'!$P$5:$P$44,0))),"") | F17: =IFERROR(IF(OR(E17="",'10_STANDARD CURVES'!$B$15=""),"",(E17-'10_STANDARD CURVES'!$B$16)/'10_STANDARD CURVES'!$B$15*IF(IFERROR(INDEX('11_ASSAY RESULTS'!$F$5:$F$44,MATCH($A17&"|"&$B17,'11_ASSAY RESULTS'!$P$5:$P$44,0)),"")="",1,IFERROR(INDEX('11_ASSAY RESULTS'!$F$5:$F$44,MATCH($A17&"|"&$B17,'11_ASSAY RESULTS'!$P$5:$P$44,0)),""))),"") | G17: =IFERROR(IF($A17="","",INDEX('11_ASSAY RESULTS'!$G$5:$G$44,MATCH($A17&"|"&$B17,'11_ASSAY RESULTS'!$P$5:$P$44,0))),"") | H17: =IFERROR(IF(OR(G17="",'10_STANDARD CURVES'!$F$15=""),"",(G17-'10_STANDARD CURVES'!$F$16)/'10_STANDARD CURVES'!$F$15*IF(IFERROR(INDEX('11_ASSAY RESULTS'!$H$5:$H$44,MATCH($A17&"|"&$B17,'11_ASSAY RESULTS'!$P$5:$P$44,0)),"")="",1,IFERROR(INDEX('11_ASSAY RESULTS'!$H$5:$H$44,MATCH($A17&"|"&$B17,'11_ASSAY RESULTS'!$P$5:$P$44,0)),""))),"") | I17: =IFERROR(IF($A17="","",INDEX('11_ASSAY RESULTS'!$I$5:$I$44,MATCH($A17&"|"&$B17,'11_ASSAY RESULTS'!$P$5:$P$44,0))),"") | J17: =IFERROR(IF($A17="","",INDEX('11_ASSAY RESULTS'!$J$5:$J$44,MATCH($A17&"|"&$B17,'11_ASSAY RESULTS'!$P$5:$P$44,0))),"") | K17: =IFERROR(IF($A17="","",INDEX('11_ASSAY RESULTS'!$L$5:$L$44,MATCH($A17&"|"&$B17,'11_ASSAY RESULTS'!$P$5:$P$44,0))),"") | L17: =IFERROR(IF($A17="","",INDEX('11_ASSAY RESULTS'!$M$5:$M$44,MATCH($A17&"|"&$B17,'11_ASSAY RESULTS'!$P$5:$P$44,0))),"") | M17: =IFERROR(IF(AND(K17="",L17=""),"",AVERAGE(K17:L17)),"") | N17: =IFERROR(IF(OR(M17="",I17="",J17=""),"",M17*J17*0.09008/I17*100),"")
A18: =IF('09_BATCH GROWTH LOG'!B18="","",'09_BATCH GROWTH LOG'!B18) -> F2 | B18: =IF('09_BATCH GROWTH LOG'!C18="","",'09_BATCH GROWTH LOG'!C18) -> 48 | C18: =IF('09_BATCH GROWTH LOG'!F18="","",'09_BATCH GROWTH LOG'!F18) -> 5.12 | D18: =IF('09_BATCH GROWTH LOG'!G18="","",'09_BATCH GROWTH LOG'!G18) -> NA | E18: =IFERROR(IF($A18="","",INDEX('11_ASSAY RESULTS'!$E$5:$E$44,MATCH($A18&"|"&$B18,'11_ASSAY RESULTS'!$P$5:$P$44,0))),"") | F18: =IFERROR(IF(OR(E18="",'10_STANDARD CURVES'!$B$15=""),"",(E18-'10_STANDARD CURVES'!$B$16)/'10_STANDARD CURVES'!$B$15*IF(IFERROR(INDEX('11_ASSAY RESULTS'!$F$5:$F$44,MATCH($A18&"|"&$B18,'11_ASSAY RESULTS'!$P$5:$P$44,0)),"")="",1,IFERROR(INDEX('11_ASSAY RESULTS'!$F$5:$F$44,MATCH($A18&"|"&$B18,'11_ASSAY RESULTS'!$P$5:$P$44,0)),""))),"") | G18: =IFERROR(IF($A18="","",INDEX('11_ASSAY RESULTS'!$G$5:$G$44,MATCH($A18&"|"&$B18,'11_ASSAY RESULTS'!$P$5:$P$44,0))),"") | H18: =IFERROR(IF(OR(G18="",'10_STANDARD CURVES'!$F$15=""),"",(G18-'10_STANDARD CURVES'!$F$16)/'10_STANDARD CURVES'!$F$15*IF(IFERROR(INDEX('11_ASSAY RESULTS'!$H$5:$H$44,MATCH($A18&"|"&$B18,'11_ASSAY RESULTS'!$P$5:$P$44,0)),"")="",1,IFERROR(INDEX('11_ASSAY RESULTS'!$H$5:$H$44,MATCH($A18&"|"&$B18,'11_ASSAY RESULTS'!$P$5:$P$44,0)),""))),"") | I18: =IFERROR(IF($A18="","",INDEX('11_ASSAY RESULTS'!$I$5:$I$44,MATCH($A18&"|"&$B18,'11_ASSAY RESULTS'!$P$5:$P$44,0))),"") | J18: =IFERROR(IF($A18="","",INDEX('11_ASSAY RESULTS'!$J$5:$J$44,MATCH($A18&"|"&$B18,'11_ASSAY RESULTS'!$P$5:$P$44,0))),"") | K18: =IFERROR(IF($A18="","",INDEX('11_ASSAY RESULTS'!$L$5:$L$44,MATCH($A18&"|"&$B18,'11_ASSAY RESULTS'!$P$5:$P$44,0))),"") | L18: =IFERROR(IF($A18="","",INDEX('11_ASSAY RESULTS'!$M$5:$M$44,MATCH($A18&"|"&$B18,'11_ASSAY RESULTS'!$P$5:$P$44,0))),"") | M18: =IFERROR(IF(AND(K18="",L18=""),"",AVERAGE(K18:L18)),"") | N18: =IFERROR(IF(OR(M18="",I18="",J18=""),"",M18*J18*0.09008/I18*100),"")
A19: =IF('09_BATCH GROWTH LOG'!B19="","",'09_BATCH GROWTH LOG'!B19) | B19: =IF('09_BATCH GROWTH LOG'!C19="","",'09_BATCH GROWTH LOG'!C19) | C19: =IF('09_BATCH GROWTH LOG'!F19="","",'09_BATCH GROWTH LOG'!F19) | D19: =IF('09_BATCH GROWTH LOG'!G19="","",'09_BATCH GROWTH LOG'!G19) | E19: =IFERROR(IF($A19="","",INDEX('11_ASSAY RESULTS'!$E$5:$E$44,MATCH($A19&"|"&$B19,'11_ASSAY RESULTS'!$P$5:$P$44,0))),"") | F19: =IFERROR(IF(OR(E19="",'10_STANDARD CURVES'!$B$15=""),"",(E19-'10_STANDARD CURVES'!$B$16)/'10_STANDARD CURVES'!$B$15*IF(IFERROR(INDEX('11_ASSAY RESULTS'!$F$5:$F$44,MATCH($A19&"|"&$B19,'11_ASSAY RESULTS'!$P$5:$P$44,0)),"")="",1,IFERROR(INDEX('11_ASSAY RESULTS'!$F$5:$F$44,MATCH($A19&"|"&$B19,'11_ASSAY RESULTS'!$P$5:$P$44,0)),""))),"") | G19: =IFERROR(IF($A19="","",INDEX('11_ASSAY RESULTS'!$G$5:$G$44,MATCH($A19&"|"&$B19,'11_ASSAY RESULTS'!$P$5:$P$44,0))),"") | H19: =IFERROR(IF(OR(G19="",'10_STANDARD CURVES'!$F$15=""),"",(G19-'10_STANDARD CURVES'!$F$16)/'10_STANDARD CURVES'!$F$15*IF(IFERROR(INDEX('11_ASSAY RESULTS'!$H$5:$H$44,MATCH($A19&"|"&$B19,'11_ASSAY RESULTS'!$P$5:$P$44,0)),"")="",1,IFERROR(INDEX('11_ASSAY RESULTS'!$H$5:$H$44,MATCH($A19&"|"&$B19,'11_ASSAY RESULTS'!$P$5:$P$44,0)),""))),"") | I19: =IFERROR(IF($A19="","",INDEX('11_ASSAY RESULTS'!$I$5:$I$44,MATCH($A19&"|"&$B19,'11_ASSAY RESULTS'!$P$5:$P$44,0))),"") | J19: =IFERROR(IF($A19="","",INDEX('11_ASSAY RESULTS'!$J$5:$J$44,MATCH($A19&"|"&$B19,'11_ASSAY RESULTS'!$P$5:$P$44,0))),"") | K19: =IFERROR(IF($A19="","",INDEX('11_ASSAY RESULTS'!$L$5:$L$44,MATCH($A19&"|"&$B19,'11_ASSAY RESULTS'!$P$5:$P$44,0))),"") | L19: =IFERROR(IF($A19="","",INDEX('11_ASSAY RESULTS'!$M$5:$M$44,MATCH($A19&"|"&$B19,'11_ASSAY RESULTS'!$P$5:$P$44,0))),"") | M19: =IFERROR(IF(AND(K19="",L19=""),"",AVERAGE(K19:L19)),"") | N19: =IFERROR(IF(OR(M19="",I19="",J19=""),"",M19*J19*0.09008/I19*100),"")
A20: =IF('09_BATCH GROWTH LOG'!B20="","",'09_BATCH GROWTH LOG'!B20) | B20: =IF('09_BATCH GROWTH LOG'!C20="","",'09_BATCH GROWTH LOG'!C20) | C20: =IF('09_BATCH GROWTH LOG'!F20="","",'09_BATCH GROWTH LOG'!F20) | D20: =IF('09_BATCH GROWTH LOG'!G20="","",'09_BATCH GROWTH LOG'!G20) | E20: =IFERROR(IF($A20="","",INDEX('11_ASSAY RESULTS'!$E$5:$E$44,MATCH($A20&"|"&$B20,'11_ASSAY RESULTS'!$P$5:$P$44,0))),"") | F20: =IFERROR(IF(OR(E20="",'10_STANDARD CURVES'!$B$15=""),"",(E20-'10_STANDARD CURVES'!$B$16)/'10_STANDARD CURVES'!$B$15*IF(IFERROR(INDEX('11_ASSAY RESULTS'!$F$5:$F$44,MATCH($A20&"|"&$B20,'11_ASSAY RESULTS'!$P$5:$P$44,0)),"")="",1,IFERROR(INDEX('11_ASSAY RESULTS'!$F$5:$F$44,MATCH($A20&"|"&$B20,'11_ASSAY RESULTS'!$P$5:$P$44,0)),""))),"") | G20: =IFERROR(IF($A20="","",INDEX('11_ASSAY RESULTS'!$G$5:$G$44,MATCH($A20&"|"&$B20,'11_ASSAY RESULTS'!$P$5:$P$44,0))),"") | H20: =IFERROR(IF(OR(G20="",'10_STANDARD CURVES'!$F$15=""),"",(G20-'10_STANDARD CURVES'!$F$16)/'10_STANDARD CURVES'!$F$15*IF(IFERROR(INDEX('11_ASSAY RESULTS'!$H$5:$H$44,MATCH($A20&"|"&$B20,'11_ASSAY RESULTS'!$P$5:$P$44,0)),"")="",1,IFERROR(INDEX('11_ASSAY RESULTS'!$H$5:$H$44,MATCH($A20&"|"&$B20,'11_ASSAY RESULTS'!$P$5:$P$44,0)),""))),"") | I20: =IFERROR(IF($A20="","",INDEX('11_ASSAY RESULTS'!$I$5:$I$44,MATCH($A20&"|"&$B20,'11_ASSAY RESULTS'!$P$5:$P$44,0))),"") | J20: =IFERROR(IF($A20="","",INDEX('11_ASSAY RESULTS'!$J$5:$J$44,MATCH($A20&"|"&$B20,'11_ASSAY RESULTS'!$P$5:$P$44,0))),"") | K20: =IFERROR(IF($A20="","",INDEX('11_ASSAY RESULTS'!$L$5:$L$44,MATCH($A20&"|"&$B20,'11_ASSAY RESULTS'!$P$5:$P$44,0))),"") | L20: =IFERROR(IF($A20="","",INDEX('11_ASSAY RESULTS'!$M$5:$M$44,MATCH($A20&"|"&$B20,'11_ASSAY RESULTS'!$P$5:$P$44,0))),"") | M20: =IFERROR(IF(AND(K20="",L20=""),"",AVERAGE(K20:L20)),"") | N20: =IFERROR(IF(OR(M20="",I20="",J20=""),"",M20*J20*0.09008/I20*100),"")
